- [Async/await](#asyncawait)
  - [Асинхронные функции](#асинхронные-функции)
  - [Await](#await)
  - [Обработка ошибок](#обработка-ошибок)


# Async/await

Существует специальный синтаксис для работы с промисами, который называется "async/await". Он удивительно просто для понимания и использования.
***

## Асинхронные функции

`async` - оно ставится прямо перед функцией:

```javascript
async function f () {
    return 1
}
```

У слова `async` один простой смысл: эта функция всегда возвращает промис. Значения других типов оборачиваются в завершившийся успешно промис автоматически.

Например, эта функция возвратит выполненный промис с результатом `1`:

```javascript
async function f () {
    return 1
}

f().then (alert) // 1
```

Можно и явно вернуть промис, результат будет одинаковым: 

```javascript
async function f () {
    return Promise.resolve(1)
}

f().then (alert) // 1
```

Так что ключевое слово `async` перед функцией гарантирует, что эта функция в любом случае вернёт промис.
***

## Await

```javascript
// работает только внутри async-функций
const value = await promise
```

Ключевое слово `await` заставит интерпретатор JavaScript ждать до тех пор, пока промис справа от `await` не выполнится. После чего оно вернёт результат и выполнение кода продолжится.

```javascript
async function f () {
    const promise = new Promise ( (resolve, reject) => {
        setTimeout( () => resolve("gotovo"), 1000)
    })

    const result = await promise // будет ждать, пока промис не выполнится

    console.log(result)
}
f()
```
<b>`await` нельзя использовать в обычных функциях. Обязательно нужно писать `async` перед `function`.</b>
***

## Обработка ошибок

Когда промис завершается успешно, `await promise` возвращает результат. Когда завершится ошибкой - будет выброшено исключение. Как если бы на месте находилось выражение `throw`:

```javascript
async function () {
    await Promise.reject (new Error("Opps"))
}
```

Делает тоже самое, что:

```javascript
async function () {
    throw new Error("Opps")
}
```

Но есть отличие, на практике промис может завершиться с ошибкой не сразу, а через некоторое время. В этом случае будет задержка, а затем `await` выбросит исключение.

Такие ошибки можно ловить, используя `try..catch` как с обычным `throw`:

```javascript
async function f () {
    try {
        const response = await fetch("http://no-such-url")
    }
    catch (err) {
        console.log(err) // TypeError: failed to fetch
    }
}
f()
```

В случае ошибки выполнения `try` прерывается и управление прыгает в начало блока `catch`. Блоком `try` можно обернуть несколько строк:

```javascript
async function f () {
    try {
        const response = await fetch("/no-user-here")
        const user = await response.json()
    }
    catch (err) {
        console.log(err)
    }
}
f()
```

Если нет `try..catch`, асинхронная функция будет возвращать завершившийся с ошибкой промис (в состоянии `rejected`). В этом случае можно использовать метод `.catch` промиса, чтобы обработать ошибку:

```javascript
async function f () {
    const response = await fetch("http://no-such-url")
}

// вернёт промис в состояние rejected
f().catch(console.log) // TypeError: failed to fetch
```